Workbook

Sheet Accueil
B2: ScanLinkPay
B4: Modèle économique et étude de faisabilité
B5: Portefeuille mobile, paiements QR et carte, caisse et stock des entreprises, réseau de fournisseurs, API pour les applications partenaires
B7: Version du 23 octobre 2026 — document de travail
B10: Résultat en un coup d’œil
B11: Scénario étudié | C11: =Hypothèses!$B$7 -> Réaliste
B12: Chiffre d’affaires net — an 1 | C12: =Synthèse!B24 -> 20622.117
B13: Chiffre d’affaires net — an 3 | C13: =Synthèse!D24 -> 143052.27
B14: Bénéfice net — total 3 ans | C14: =Synthèse!E32 -> 24821.923
B15: Premier mois bénéficiaire | C15: =Synthèse!H5 -> Mois 16
B16: Besoin de trésorerie maximal | C16: =Synthèse!H7 -> 15455.281
B17: Paiements nécessaires pour l’objectif (par mois) | C17: =Rentabilité!B23 -> 237815.82
B19: Les onglets
B20: Hypothèses | C20: Tous les prix, frais, coûts et applications partenaires. C’est ici qu’on modifie.
B21: Scénarios | C21: Pessimiste / Réaliste / Optimiste : rythme d’inscription, volumes, départs.
B22: Prévisions | C22: 36 mois : utilisateurs, volumes, recettes par source, coûts, bénéfice, trésorerie.
B23: Synthèse | C23: Les 3 années côte à côte, repères clés et graphiques.
B24: Prix | C24: Choisir les prix des abonnements (entreprise, Fournisseur, formule annuelle), recette par utilisateur.
B25: Rentabilité | C25: Seuil de rentabilité, objectif de 1 000 £ par mois, ce que rapportent les applications partenaires.
B26: Retraits | C26: Frais de retrait face au coût FlexPaie : gain ou perte.
B27: Sensibilité | C27: Commission × volume : le résultat du mois 12.
B29: Code couleur
B30: Texte bleu | C30: Valeur saisie : hypothèse à discuter, modifiable
B31: Fond jaune | C31: Hypothèse clé (elle change beaucoup le résultat)
B32: Texte vert | C32: Valeur reprise d’un autre onglet
B33: Texte noir | C33: Calcul automatique : ne pas modifier
B35: Sources des tarifs
B36: • | C36: Commission 2,5 % (min 0,05 $, max 100 $), retrait 1 %, transfert gratuit : valeurs par défaut du code ScanLinkPay (migrations 002, 007, 008), réglables par le super admin.
B37: • | C37: FlexPaie : ~2 % sur les retraits (à notre charge), ~2,5 % à 3 % sur les encaissements (payés par le client) — docs/FLEXPAIE.md.
B38: • | C38: Abonnement Fournisseur 10 $ / mois, mois offerts sur l’année et essai réglés par le super admin (décision du 23/10/2026, migration 084).
B39: • | C39: Mes dépenses Pro 5 000 CDF / mois (migration 025). Prix de l’abonnement entreprise : à remplacer par le prix réel.
B40: • | C40: Volumes, adoption, coûts d’équipe et de marketing : hypothèses de travail à discuter, pas des chiffres constatés.

Sheet Hypothèses
A1: Hypothèses — tout ce qui se modifie
A2: Bleu = valeur à discuter / modifier · Jaune = hypothèse clé · Les autres onglets se recalculent seuls.
A5: Général
A6: Paramètre | B6: Valeur | D6: Source / commentaire
A7: Scénario étudié | B7: Réaliste | D7: Choisir Pessimiste, Réaliste ou Optimiste (liste). Les paramètres de chaque scénario sont dans l’onglet Scénarios.
A8: Taux de change (CDF pour 1 USD) | B8: 2850 | D8: Taux indicatif à mettre à jour (le super admin le règle aussi dans l’application). Le modèle est en USD.
A9: Taux de change (USD pour 1 GBP) | B9: 1.27 | D9: Pour l’objectif exprimé en livres sterling (onglet Rentabilité). À mettre à jour.
A10: TVA RDC sur nos services | B10: 0.16 | D10: TVA standard RDC 16 %. Mettre 0 si non assujetti. À confirmer avec le comptable.
A11: Nos prix incluent la TVA ? (1 = oui, 0 = non) | B11: 1 | D11: 1 = prudent : une part de chaque recette est reversée à l’État.
A12: Impôt sur les bénéfices (IBP) | B12: 0.3 | D12: Taux de droit commun RDC (30 %). À confirmer avec le comptable.
A14: Paiements chez les commerçants et entreprises (tarifs du code)
A15: Paramètre | B15: Valeur | D15: Source / commentaire
A16: Commission ScanLinkPay sur un paiement | B16: 0.025 | D16: Règle par défaut du code (USD et CDF : 2,5 %, min 0,05 $, max 100 $). Modifiable par le super admin → Commissions.
A17: Frais FlexPaie à l’encaissement supportés par ScanLinkPay | B17: 0 | D17: FlexPaie facture ~2,5 % (3 % par carte) au PAYEUR, en plus du montant (docs/FLEXPAIE.md). Coût 0 pour ScanLinkPay tant que c’est le cas.
A18: Part de l’argent reçu retirée vers Mobile Money | B18: 0.6 | D18: Hypothèse : le reste reste dans les portefeuilles ou repart en paiements.
A19: Frais de retrait facturés à l’utilisateur | B19: 0.01 | D19: Valeur actuelle du code : 1 %. ⚠ Inférieure au coût FlexPaie : voir l’onglet Retraits (recommandé ≥ 2,5 %).
A20: Coût FlexPaie d’un retrait (payout) | B20: 0.02 | D20: Environ 2 % selon FlexPaie (docs/FLEXPAIE.md). À confirmer sur le contrat.
A21: Frais de transfert entre portefeuilles | B21: 0 | D21: Gratuit dans le code (attirer les utilisateurs).
A22: Transferts par client actif et par mois ($) | B22: 30 | D22: Hypothèse.
A23: Montant moyen d’un paiement chez un commerçant ($) | B23: 20 | D23: Sert à compter les transactions (onglet Rentabilité).
A25: Abonnements (prix réglés par le super admin)
A26: Paramètre | B26: Valeur | D26: Source / commentaire
A27: Abonnement entreprise — prix par mois ($) | B27: 15 | D27: À remplacer par votre prix réel (super admin → Tarifs → Abonnements). Tout inclus : caisse, ventes, stock, rapports…
A28: Abonnement entreprise — essai gratuit (jours) | B28: 30 | D28: Réglage super admin (informatif dans ce modèle).
A29: Abonnement Fournisseur — prix par mois ($) | B29: 10 | D29: Décision du 23/10 : 10 $ par mois (migration 084).
A30: Abonnement Fournisseur — mois offerts sur l’année | B30: 2 | D30: L’année = 12 mois pour le prix de (12 − N).
A31: Part des fournisseurs qui paient à l’année | B31: 0.3 | D31: Hypothèse.
A32: Mes dépenses « Pro » — prix par mois (CDF) | B32: 5000 | D32: Valeur par défaut du code (5 000 CDF), réglable par le super admin.
A34: Applications partenaires qui utilisent l’API ScanLinkPay
A35: Paramètre | B35: Valeur | D35: Source / commentaire
A36: Commission sur les paiements reçus par API : voir le tableau ci-dessous (une ligne par application).
A37: Application | B37: Mois de début | C37: Transactions / mois au début | D37: Montant moyen ($) | E37: Croissance mensuelle | F37: Commission
A38: HotelSaver (abonnements des hôtels + acomptes des clients) | B38: 1 | C38: 40 | D38: 20 | E38: 0.06 | F38: =Hypothèses!$B$16 -> 0.025
A39: Application partenaire 2 | B39: 6 | C39: 100 | D39: 15 | E39: 0.08 | F39: =Hypothèses!$B$16 -> 0.025
A40: Application partenaire 3 | B40: 12 | C40: 150 | D40: 10 | E40: 0.08 | F40: =Hypothèses!$B$16 -> 0.025
A41: Application partenaire 4 | B41: 18 | C41: 200 | D41: 10 | E41: 0.08 | F41: =Hypothèses!$B$16 -> 0.025
A42: Mois de début 0 ou vide = application pas encore branchée. La commission suit par défaut la règle standard (modifiable ligne par ligne).
A44: Coûts fixes mensuels ($)
A45: Paramètre | B45: Valeur | D45: Source / commentaire
A46: Hébergement API + site (Render) | B46: 32 | D46: Render : API Standard ~25 $ + site ~7 $ (à vérifier sur la facture).
...

Sheet Scénarios
A1: Scénarios — rythme d’adoption
A2: Colonne « Actif » = le scénario choisi dans Hypothèses. Modifier les colonnes bleues.
A4: Paramètre | B4: Pessimiste | C4: Réaliste | D4: Optimiste | E4: Actif | F4: Commentaire
A5: Entreprises au départ | B5: 3 | C5: 5 | D5: 10 | E5: =INDEX(B5:D5,MATCH(Hypothèses!$B$7,$B$4:$D$4,0)) -> 5 | F5: Entreprises déjà inscrites (supermarchés, électronique).
A6: Commerçants indépendants au départ | B6: 5 | C6: 10 | D6: 25 | E6: =INDEX(B6:D6,MATCH(Hypothèses!$B$7,$B$4:$D$4,0)) -> 10
A7: Clients actifs au départ | B7: 100 | C7: 200 | D7: 500 | E7: =INDEX(B7:D7,MATCH(Hypothèses!$B$7,$B$4:$D$4,0)) -> 200
A8: Nouvelles entreprises par mois (au début) | B8: 1 | C8: 3 | D8: 6 | E8: =INDEX(B8:D8,MATCH(Hypothèses!$B$7,$B$4:$D$4,0)) -> 3
A9: Nouveaux commerçants par mois (au début) | B9: 5 | C9: 10 | D9: 20 | E9: =INDEX(B9:D9,MATCH(Hypothèses!$B$7,$B$4:$D$4,0)) -> 10
A10: Nouveaux clients par mois (au début) | B10: 80 | C10: 200 | D10: 400 | E10: =INDEX(B10:D10,MATCH(Hypothèses!$B$7,$B$4:$D$4,0)) -> 200
A11: Croissance mensuelle des inscriptions — an 1 | B11: 0.04 | C11: 0.08 | D11: 0.12 | E11: =INDEX(B11:D11,MATCH(Hypothèses!$B$7,$B$4:$D$4,0)) -> 0.08 | F11: Les nouvelles inscriptions augmentent chaque mois de ce pourcentage.
A12: Croissance mensuelle des inscriptions — ans 2 et 3 | B12: 0.02 | C12: 0.04 | D12: 0.06 | E12: =INDEX(B12:D12,MATCH(Hypothèses!$B$7,$B$4:$D$4,0)) -> 0.04
A13: Départs mensuels (entreprises, commerçants) | B13: 0.05 | C13: 0.03 | D13: 0.02 | E13: =INDEX(B13:D13,MATCH(Hypothèses!$B$7,$B$4:$D$4,0)) -> 0.03 | F13: Churn.
A14: Départs mensuels (clients) | B14: 0.08 | C14: 0.05 | D14: 0.04 | E14: =INDEX(B14:D14,MATCH(Hypothèses!$B$7,$B$4:$D$4,0)) -> 0.05
A15: Entreprises qui paient après l’essai | B15: 0.4 | C15: 0.6 | D15: 0.75 | E15: =INDEX(B15:D15,MATCH(Hypothèses!$B$7,$B$4:$D$4,0)) -> 0.6
A16: Paiements reçus par commerçant et par mois ($) | B16: 100 | C16: 300 | D16: 600 | E16: =INDEX(B16:D16,MATCH(Hypothèses!$B$7,$B$4:$D$4,0)) -> 300 | F16: Via QR / carte ScanLinkPay.
A17: Paiements ScanLinkPay reçus par entreprise et par mois ($) | B17: 300 | C17: 800 | D17: 1500 | E17: =INDEX(B17:D17,MATCH(Hypothèses!$B$7,$B$4:$D$4,0)) -> 800 | F17: Caisse + ventes : seulement la part payée par ScanLinkPay (QR, carte), pas les espèces — faible au début.
A18: Clients qui prennent « Mes dépenses Pro » | B18: 0.01 | C18: 0.02 | D18: 0.04 | E18: =INDEX(B18:D18,MATCH(Hypothèses!$B$7,$B$4:$D$4,0)) -> 0.02
A19: Entreprises qui deviennent fournisseurs | B19: 0.08 | C19: 0.15 | D19: 0.25 | E19: =INDEX(B19:D19,MATCH(Hypothèses!$B$7,$B$4:$D$4,0)) -> 0.15
A20: Fournisseurs qui paient après l’essai | B20: 0.4 | C20: 0.6 | D20: 0.75 | E20: =INDEX(B20:D20,MATCH(Hypothèses!$B$7,$B$4:$D$4,0)) -> 0.6
A21: Commandes reçues par fournisseur et par mois | B21: 4 | C21: 8 | D21: 15 | E21: =INDEX(B21:D21,MATCH(Hypothèses!$B$7,$B$4:$D$4,0)) -> 8
A22: Montant moyen d’une commande entre entreprises ($) | B22: 150 | C22: 300 | D22: 500 | E22: =INDEX(B22:D22,MATCH(Hypothèses!$B$7,$B$4:$D$4,0)) -> 300
A23: Part des commandes payées par ScanLinkPay | B23: 0.25 | C23: 0.4 | D23: 0.6 | E23: =INDEX(B23:D23,MATCH(Hypothèses!$B$7,$B$4:$D$4,0)) -> 0.4 | F23: Le reste est payé en espèces / Mobile Money hors application (pas de commission).
A24: Multiplicateur des volumes des applications partenaires | B24: 0.5 | C24: 1 | D24: 1.5 | E24: =INDEX(B24:D24,MATCH(Hypothèses!$B$7,$B$4:$D$4,0)) -> 1 | F24: Appliqué au tableau des applications (Hypothèses).

Sheet Prévisions
A1: Prévisions mensuelles sur 3 ans (USD)
A2: Tout est calculé à partir des onglets Hypothèses et Scénarios. Ne rien saisir ici.
A4: Mois | C4: 1 | D4: 2 | E4: 3 | F4: 4 | G4: 5 | H4: 6 | I4: 7 | J4: 8 | K4: 9 | L4: 10 | M4: 11 | N4: 12 | O4: 13 | P4: 14 | Q4: 15 | R4: 16 | S4: 17 | T4: 18 | U4: 19 | V4: 20 | W4: 21 | X4: 22 | Y4: 23 | Z4: 24 | AA4: 25 | AB4: 26 | AC4: 27 | AD4: 28 | AE4: 29 | AF4: 30 | AG4: 31 | AH4: 32 | AI4: 33 | AJ4: 34 | AK4: 35 | AL4: 36
A5: Année | C5: =INT((C4-1)/12)+1 -> 1 | D5: =INT((D4-1)/12)+1 -> 1 | E5: =INT((E4-1)/12)+1 -> 1 | F5: =INT((F4-1)/12)+1 -> 1 | G5: =INT((G4-1)/12)+1 -> 1 | H5: =INT((H4-1)/12)+1 -> 1 | I5: =INT((I4-1)/12)+1 -> 1 | J5: =INT((J4-1)/12)+1 -> 1 | ... AL5: =INT((AL4-1)/12)+1 -> 3
A7: Utilisateurs
A8: Facteur de croissance des inscriptions | B8: x | C8: =1 -> 1 | D8: =C8*(1+IF(D$5=1,Scénarios!$E$11,Scénarios!$E$12)) -> 1.08 | E8: =D8*(1+IF(E$5=1,Scénarios!$E$11,Scénarios!$E$12)) -> 1.1664 | F8: =E8*(1+IF(F$5=1,Scénarios!$E$11,Scénarios!$E$12)) -> 1.259712 | G8: =F8*(1+IF(G$5=1,Scénarios!$E$11,Scénarios!$E$12)) -> 1.360489 | H8: =G8*(1+IF(H$5=1,Scénarios!$E$11,Scénarios!$E$12)) -> 1.4693281 | I8: =H8*(1+IF(I$5=1,Scénarios!$E$11,Scénarios!$E$12)) -> 1.5868743 | J8: =I8*(1+IF(J$5=1,Scénarios!$E$11,Scénarios!$E$12)) -> 1.7138243 | K8: =J8*(1+IF(K$5=1,Scénarios!$E$11,Scénarios!$E$12)) -> 1.8509302 | ... AL8: =AK8*(1+IF(AL$5=1,Scénarios!$E$11,Scénarios!$E$12)) -> 5.9767
A9: Nouvelles entreprises | B9: nb | C9: =Scénarios!$E$8*C8 -> 3 | D9: =Scénarios!$E$8*D8 -> 3.24 | E9: =Scénarios!$E$8*E8 -> 3.4992 | F9: =Scénarios!$E$8*F8 -> 3.779136 | G9: =Scénarios!$E$8*G8 -> 4.0814669 | H9: =Scénarios!$E$8*H8 -> 4.4079842 | I9: =Scénarios!$E$8*I8 -> 4.760623 | J9: =Scénarios!$E$8*J8 -> 5.1414728 | ... AL9: =Scénarios!$E$8*AL8 -> 17.9301
A10: Entreprises actives | B10: nb | C10: =Scénarios!$E$5*(1-Scénarios!$E$13)+C9 -> 7.85 | D10: =C10*(1-Scénarios!$E$13)+D9 -> 10.8545 | E10: =D10*(1-Scénarios!$E$13)+E9 -> 14.028065 | F10: =E10*(1-Scénarios!$E$13)+F9 -> 17.386359 | G10: =F10*(1-Scénarios!$E$13)+G9 -> 20.946235 | H10: =G10*(1-Scénarios!$E$13)+H9 -> 24.725832 | I10: =H10*(1-Scénarios!$E$13)+I9 -> 28.74468 | J10: =I10*(1-Scénarios!$E$13)+J9 -> 33.023813 | K10: =J10*(1-Scénarios!$E$13)+K9 -> 37.585889 | ... AL10: =AK10*(1-Scénarios!$E$13)+AL9 -> 241.98178
A11: Entreprises qui paient l’abonnement | B11: nb | C11: =C10*Scénarios!$E$15 -> 4.71 | D11: =D10*Scénarios!$E$15 -> 6.5127 | E11: =E10*Scénarios!$E$15 -> 8.416839 | F11: =F10*Scénarios!$E$15 -> 10.431815 | G11: =G10*Scénarios!$E$15 -> 12.567741 | H11: =H10*Scénarios!$E$15 -> 14.835499 | I11: =I10*Scénarios!$E$15 -> 17.246808 | J11: =J10*Scénarios!$E$15 -> 19.814288 | ... AL11: =AL10*Scénarios!$E$15 -> 145.18907
A12: Nouveaux commerçants | B12: nb | C12: =Scénarios!$E$9*C8 -> 10 | D12: =Scénarios!$E$9*D8 -> 10.8 | E12: =Scénarios!$E$9*E8 -> 11.664 | F12: =Scénarios!$E$9*F8 -> 12.59712 | G12: =Scénarios!$E$9*G8 -> 13.60489 | H12: =Scénarios!$E$9*H8 -> 14.693281 | I12: =Scénarios!$E$9*I8 -> 15.868743 | J12: =Scénarios!$E$9*J8 -> 17.138243 | ... AL12: =Scénarios!$E$9*AL8 -> 59.767
A13: Commerçants actifs | B13: nb | C13: =Scénarios!$E$6*(1-Scénarios!$E$13)+C12 -> 19.7 | D13: =C13*(1-Scénarios!$E$13)+D12 -> 29.909 | E13: =D13*(1-Scénarios!$E$13)+E12 -> 40.67573 | F13: =E13*(1-Scénarios!$E$13)+F12 -> 52.052578 | G13: =F13*(1-Scénarios!$E$13)+G12 -> 64.09589 | H13: =G13*(1-Scénarios!$E$13)+H12 -> 76.866294 | I13: =H13*(1-Scénarios!$E$13)+I12 -> 90.429049 | J13: =I13*(1-Scénarios!$E$13)+J12 -> 104.85442 | K13: =J13*(1-Scénarios!$E$13)+K12 -> 120.21809 | ... AL13: =AK13*(1-Scénarios!$E$13)+AL12 -> 804.37908
A14: Nouveaux clients | B14: nb | C14: =Scénarios!$E$10*C8 -> 200 | D14: =Scénarios!$E$10*D8 -> 216 | E14: =Scénarios!$E$10*E8 -> 233.28 | F14: =Scénarios!$E$10*F8 -> 251.9424 | G14: =Scénarios!$E$10*G8 -> 272.09779 | H14: =Scénarios!$E$10*H8 -> 293.86562 | I14: =Scénarios!$E$10*I8 -> 317.37486 | J14: =Scénarios!$E$10*J8 -> 342.76485 | ... AL14: =Scénarios!$E$10*AL8 -> 1195.34
A15: Clients actifs | B15: nb | C15: =Scénarios!$E$7*(1-Scénarios!$E$14)+C14 -> 390 | D15: =C15*(1-Scénarios!$E$14)+D14 -> 586.5 | E15: =D15*(1-Scénarios!$E$14)+E14 -> 790.455 | F15: =E15*(1-Scénarios!$E$14)+F14 -> 1002.8746 | G15: =F15*(1-Scénarios!$E$14)+G14 -> 1224.8287 | H15: =G15*(1-Scénarios!$E$14)+H14 -> 1457.4529 | I15: =H15*(1-Scénarios!$E$14)+I14 -> 1701.9551 | J15: =I15*(1-Scénarios!$E$14)+J14 -> 1959.6222 | K15: =J15*(1-Scénarios!$E$14)+K14 -> 2231.8271 | ... AL15: =AK15*(1-Scénarios!$E$14)+AL14 -> 13159.399
A16: Fournisseurs (réseau entre entreprises) | B16: nb | C16: =C10*Scénarios!$E$19 -> 1.1775 | D16: =D10*Scénarios!$E$19 -> 1.628175 | E16: =E10*Scénarios!$E$19 -> 2.1042097 | F16: =F10*Scénarios!$E$19 -> 2.6079539 | G16: =G10*Scénarios!$E$19 -> 3.1419353 | H16: =H10*Scénarios!$E$19 -> 3.7088749 | I16: =I10*Scénarios!$E$19 -> 4.311702 | J16: =J10*Scénarios!$E$19 -> 4.9535719 | ... AL16: =AL10*Scénarios!$E$19 -> 36.297267
A17: Fournisseurs qui paient l’abonnement Fournisseur | B17: nb | C17: =C16*Scénarios!$E$20 -> 0.7065 | D17: =D16*Scénarios!$E$20 -> 0.976905 | E17: =E16*Scénarios!$E$20 -> 1.2625259 | F17: =F16*Scénarios!$E$20 -> 1.5647723 | G17: =G16*Scénarios!$E$20 -> 1.8851612 | H17: =H16*Scénarios!$E$20 -> 2.2253249 | I17: =I16*Scénarios!$E$20 -> 2.5870212 | J17: =J16*Scénarios!$E$20 -> 2.9721431 | ... AL17: =AL16*Scénarios!$E$20 -> 21.77836
A18: Utilisateurs actifs (total) | B18: nb | C18: =C10+C13+C15 -> 417.55 | D18: =D10+D13+D15 -> 627.2635 | E18: =E10+E13+E15 -> 845.1588 | F18: =F10+F13+F15 -> 1072.3136 | G18: =G10+G13+G15 -> 1309.8708 | H18: =H10+H13+H15 -> 1559.045 | I18: =I10+I13+I15 -> 1821.1288 | J18: =J10+J13+J15 -> 2097.5004 | ... AL18: =AL10+AL13+AL15 -> 14205.76
A20: Volumes d’argent
A21: Paiements reçus par commerçants et entreprises | B21: $ | C21: =C13*Scénarios!$E$16+C10*Scénarios!$E$17 -> 12190 | D21: =D13*Scénarios!$E$16+D10*Scénarios!$E$17 -> 17656.3 | E21: =E13*Scénarios!$E$16+E10*Scénarios!$E$17 -> 23425.171 | F21: =F13*Scénarios!$E$16+F10*Scénarios!$E$17 -> 29524.861 | G21: =G13*Scénarios!$E$16+G10*Scénarios!$E$17 -> 35985.755 | H21: =H13*Scénarios!$E$16+H10*Scénarios!$E$17 -> 42840.554 | I21: =I13*Scénarios!$E$16+I10*Scénarios!$E$17 -> 50124.459 | J21: =J13*Scénarios!$E$16+J10*Scénarios!$E$17 -> 57875.376 | ... AL21: =AL13*Scénarios!$E$16+AL10*Scénarios!$E$17 -> 434899.15
A22: Commandes entre entreprises payées par ScanLinkPay | B22: $ | C22: =C17*Scénarios!$E$21*Scénarios!$E$22*Scénarios!$E$23 -> 678.24 | D22: =D17*Scénarios!$E$21*Scénarios!$E$22*Scénarios!$E$23 -> 937.8288 | E22: =E17*Scénarios!$E$21*Scénarios!$E$22*Scénarios!$E$23 -> 1212.0248 | F22: =F17*Scénarios!$E$21*Scénarios!$E$22*Scénarios!$E$23 -> 1502.1814 | G22: =G17*Scénarios!$E$21*Scénarios!$E$22*Scénarios!$E$23 -> 1809.7547 | H22: =H17*Scénarios!$E$21*Scénarios!$E$22*Scénarios!$E$23 -> 2136.3119 | I22: =I17*Scénarios!$E$21*Scénarios!$E$22*Scénarios!$E$23 -> 2483.5404 | J22: =J17*Scénarios!$E$21*Scénarios!$E$22*Scénarios!$E$23 -> 2853.2574 | ... AL22: =AL17*Scénarios!$E$21*Scénarios!$E$22*Scénarios!$E$23 -> 20907.226
A23: ="API — "&Hypothèses!$A$38 -> API — HotelSaver (abonnements des hôtels + acomptes des clients) | B23: $ | C23: =IF(AND(Hypothèses!$B$38>0,C$4>=Hypothèses!$B$38),Hypothèses!$C$38*(1+Hypothèses!$E$38)^(C$4-Hypothèses!$B$38)*Hypothèses!$D$38*Scénarios!$E$24,0) -> 800 | D23: =IF(AND(Hypothèses!$B$38>0,D$4>=Hypothèses!$B$38),Hypothèses!$C$38*(1+Hypothèses!$E$38)^(D$4-Hypothèses!$B$38)*Hypothèses!$D$38*Scénarios!$E$24,0) -> 848 | E23: =IF(AND(Hypothèses!$B$38>0,E$4>=Hypothèses!$B$38),Hypothèses!$C$38*(1+Hypothèses!$E$38)^(E$4-Hypothèses!$B$38)*Hypothèses!$D$38*Scénarios!$E$24,0) -> 898.88 | F23: =IF(AND(Hypothèses!$B$38>0,F$4>=Hypothèses!$B$38),Hypothèses!$C$38*(1+Hypothèses!$E$38)^(F$4-Hypothèses!$B$38)*Hypothèses!$D$38*Scénarios!$E$24,0) -> 952.8128 | G23: =IF(AND(Hypothèses!$B$38>0,G$4>=Hypothèses!$B$38),Hypothèses!$C$38*(1+Hypothèses!$E$38)^(G$4-Hypothèses!$B$38)*Hypothèses!$D$38*Scénarios!$E$24,0) -> 1009.9816 | H23: =IF(AND(Hypothèses!$B$38>0,H$4>=Hypothèses!$B$38),Hypothèses!$C$38*(1+Hypothèses!$E$38)^(H$4-Hypothèses!$B$38)*Hypothèses!$D$38*Scénarios!$E$24,0) -> 1070.5805 | I23: =IF(AND(Hypothèses!$B$38>0,I$4>=Hypothèses!$B$38),Hypothèses!$C$38*(1+Hypothèses!$E$38)^(I$4-Hypothèses!$B$38)*Hypothèses!$D$38*Scénarios!$E$24,0) -> 1134.8153 | J23: =IF(AND(Hypothèses!$B$38>0,J$4>=Hypothèses!$B$38),Hypothèses!$C$38*(1+Hypothèses!$E$38)^(J$4-Hypothèses!$B$38)*Hypothèses!$D$38*Scénarios!$E$24,0) -> 1202.9042 | ... AL23: =IF(AND(Hypothèses!$B$38>0,AL$4>=Hypothèses!$B$38),Hypothèses!$C$38*(1+Hypothèses!$E$38)^(AL$4-Hypothèses!$B$38)*Hypothèses!$D$38*Scénarios!$E$24,0) -> 6148.8694
A24: ="API — "&Hypothèses!$A$39 -> API — Application partenaire 2 | B24: $ | C24: =IF(AND(Hypothèses!$B$39>0,C$4>=Hypothèses!$B$39),Hypothèses!$C$39*(1+Hypothèses!$E$39)^(C$4-Hypothèses!$B$39)*Hypothèses!$D$39*Scénarios!$E$24,0) -> 0 | D24: =IF(AND(Hypothèses!$B$39>0,D$4>=Hypothèses!$B$39),Hypothèses!$C$39*(1+Hypothèses!$E$39)^(D$4-Hypothèses!$B$39)*Hypothèses!$D$39*Scénarios!$E$24,0) -> 0 | E24: =IF(AND(Hypothèses!$B$39>0,E$4>=Hypothèses!$B$39),Hypothèses!$C$39*(1+Hypothèses!$E$39)^(E$4-Hypothèses!$B$39)*Hypothèses!$D$39*Scénarios!$E$24,0) -> 0 | F24: =IF(AND(Hypothèses!$B$39>0,F$4>=Hypothèses!$B$39),Hypothèses!$C$39*(1+Hypothèses!$E$39)^(F$4-Hypothèses!$B$39)*Hypothèses!$D$39*Scénarios!$E$24,0) -> 0 | G24: =IF(AND(Hypothèses!$B$39>0,G$4>=Hypothèses!$B$39),Hypothèses!$C$39*(1+Hypothèses!$E$39)^(G$4-Hypothèses!$B$39)*Hypothèses!$D$39*Scénarios!$E$24,0) -> 0 | H24: =IF(AND(Hypothèses!$B$39>0,H$4>=Hypothèses!$B$39),Hypothèses!$C$39*(1+Hypothèses!$E$39)^(H$4-Hypothèses!$B$39)*Hypothèses!$D$39*Scénarios!$E$24,0) -> 1500 | I24: =IF(AND(Hypothèses!$B$39>0,I$4>=Hypothèses!$B$39),Hypothèses!$C$39*(1+Hypothèses!$E$39)^(I$4-Hypothèses!$B$39)*Hypothèses!$D$39*Scénarios!$E$24,0) -> 1620 | J24: =IF(AND(Hypothèses!$B$39>0,J$4>=Hypothèses!$B$39),Hypothèses!$C$39*(1+Hypothèses!$E$39)^(J$4-Hypothèses!$B$39)*Hypothèses!$D$39*Scénarios!$E$24,0) -> 1749.6 | ... AL24: =IF(AND(Hypothèses!$B$39>0,AL$4>=Hypothèses!$B$39),Hypothèses!$C$39*(1+Hypothèses!$E$39)^(AL$4-Hypothèses!$B$39)*Hypothèses!$D$39*Scénarios!$E$24,0) -> 15093.985
A25: ="API — "&Hypothèses!$A$40 -> API — Application partenaire 3 | B25: $ | C25: =IF(AND(Hypothèses!$B$40>0,C$4>=Hypothèses!$B$40),Hypothèses!$C$40*(1+Hypothèses!$E$40)^(C$4-Hypothèses!$B$40)*Hypothèses!$D$40*Scénarios!$E$24,0) -> 0 | D25: =IF(AND(Hypothèses!$B$40>0,D$4>=Hypothèses!$B$40),Hypothèses!$C$40*(1+Hypothèses!$E$40)^(D$4-Hypothèses!$B$40)*Hypothèses!$D$40*Scénarios!$E$24,0) -> 0 | E25: =IF(AND(Hypothèses!$B$40>0,E$4>=Hypothèses!$B$40),Hypothèses!$C$40*(1+Hypothèses!$E$40)^(E$4-Hypothèses!$B$40)*Hypothèses!$D$40*Scénarios!$E$24,0) -> 0 | F25: =IF(AND(Hypothèses!$B$40>0,F$4>=Hypothèses!$B$40),Hypothèses!$C$40*(1+Hypothèses!$E$40)^(F$4-Hypothèses!$B$40)*Hypothèses!$D$40*Scénarios!$E$24,0) -> 0 | G25: =IF(AND(Hypothèses!$B$40>0,G$4>=Hypothèses!$B$40),Hypothèses!$C$40*(1+Hypothèses!$E$40)^(G$4-Hypothèses!$B$40)*Hypothèses!$D$40*Scénarios!$E$24,0) -> 0 | H25: =IF(AND(Hypothèses!$B$40>0,H$4>=Hypothèses!$B$40),Hypothèses!$C$40*(1+Hypothèses!$E$40)^(H$4-Hypothèses!$B$40)*Hypothèses!$D$40*Scénarios!$E$24,0) -> 0 | I25: =IF(AND(Hypothèses!$B$40>0,I$4>=Hypothèses!$B$40),Hypothèses!$C$40*(1+Hypothèses!$E$40)^(I$4-Hypothèses!$B$40)*Hypothèses!$D$40*Scénarios!$E$24,0) -> 0 | J25: =IF(AND(Hypothèses!$B$40>0,J$4>=Hypothèses!$B$40),Hypothèses!$C$40*(1+Hypothèses!$E$40)^(J$4-Hypothèses!$B$40)*Hypothèses!$D$40*Scénarios!$E$24,0) -> 0 | ... AL25: =IF(AND(Hypothèses!$B$40>0,AL$4>=Hypothèses!$B$40),Hypothèses!$C$40*(1+Hypothèses!$E$40)^(AL$4-Hypothèses!$B$40)*Hypothèses!$D$40*Scénarios!$E$24,0) -> 9511.7711
A26: ="API — "&Hypothèses!$A$41 -> API — Application partenaire 4 | B26: $ | C26: =IF(AND(Hypothèses!$B$41>0,C$4>=Hypothèses!$B$41),Hypothèses!$C$41*(1+Hypothèses!$E$41)^(C$4-Hypothèses!$B$41)*Hypothèses!$D$41*Scénarios!$E$24,0) -> 0 | D26: =IF(AND(Hypothèses!$B$41>0,D$4>=Hypothèses!$B$41),Hypothèses!$C$41*(1+Hypothèses!$E$41)^(D$4-Hypothèses!$B$41)*Hypothèses!$D$41*Scénarios!$E$24,0) -> 0 | E26: =IF(AND(Hypothèses!$B$41>0,E$4>=Hypothèses!$B$41),Hypothèses!$C$41*(1+Hypothèses!$E$41)^(E$4-Hypothèses!$B$41)*Hypothèses!$D$41*Scénarios!$E$24,0) -> 0 | F26: =IF(AND(Hypothèses!$B$41>0,F$4>=Hypothèses!$B$41),Hypothèses!$C$41*(1+Hypothèses!$E$41)^(F$4-Hypothèses!$B$41)*Hypothèses!$D$41*Scénarios!$E$24,0) -> 0 | G26: =IF(AND(Hypothèses!$B$41>0,G$4>=Hypothèses!$B$41),Hypothèses!$C$41*(1+Hypothèses!$E$41)^(G$4-Hypothèses!$B$41)*Hypothèses!$D$41*Scénarios!$E$24,0) -> 0 | H26: =IF(AND(Hypothèses!$B$41>0,H$4>=Hypothèses!$B$41),Hypothèses!$C$41*(1+Hypothèses!$E$41)^(H$4-Hypothèses!$B$41)*Hypothèses!$D$41*Scénarios!$E$24,0) -> 0 | I26: =IF(AND(Hypothèses!$B$41>0,I$4>=Hypothèses!$B$41),Hypothèses!$C$41*(1+Hypothèses!$E$41)^(I$4-Hypothèses!$B$41)*Hypothèses!$D$41*Scénarios!$E$24,0) -> 0 | J26: =IF(AND(Hypothèses!$B$41>0,J$4>=Hypothèses!$B$41),Hypothèses!$C$41*(1+Hypothèses!$E$41)^(J$4-Hypothèses!$B$41)*Hypothèses!$D$41*Scénarios!$E$24,0) -> 0 | ... AL26: =IF(AND(Hypothèses!$B$41>0,AL$4>=Hypothèses!$B$41),Hypothèses!$C$41*(1+Hypothèses!$E$41)^(AL$4-Hypothèses!$B$41)*Hypothèses!$D$41*Scénarios!$E$24,0) -> 7992.039
A27: Paiements reçus via l’API (toutes applications) | B27: $ | C27: =SUM(C23:C26) -> 800 | D27: =SUM(D23:D26) -> 848 | E27: =SUM(E23:E26) -> 898.88 | F27: =SUM(F23:F26) -> 952.8128 | G27: =SUM(G23:G26) -> 1009.9816 | H27: =SUM(H23:H26) -> 2570.5805 | I27: =SUM(I23:I26) -> 2754.8153 | J27: =SUM(J23:J26) -> 2952.5042 | ... AL27: =SUM(AL23:AL26) -> 38746.665
A28: Retraits vers Mobile Money | B28: $ | C28: =(C21+C22)*Hypothèses!$B$18 -> 7720.944 | D28: =(D21+D22)*Hypothèses!$B$18 -> 11156.477 | E28: =(E21+E22)*Hypothèses!$B$18 -> 14782.317 | F28: =(F21+F22)*Hypothèses!$B$18 -> 18616.225 | G28: =(G21+G22)*Hypothèses!$B$18 -> 22677.306 | H28: =(H21+H22)*Hypothèses!$B$18 -> 26986.12 | I28: =(I21+I22)*Hypothèses!$B$18 -> 31564.8 | J28: =(J21+J22)*Hypothèses!$B$18 -> 36437.18 | ... AL28: =(AL21+AL22)*Hypothèses!$B$18 -> 273483.82
A29: Transferts entre portefeuilles | B29: $ | C29: =C15*Hypothèses!$B$22 -> 11700 | D29: =D15*Hypothèses!$B$22 -> 17595 | E29: =E15*Hypothèses!$B$22 -> 23713.65 | F29: =F15*Hypothèses!$B$22 -> 30086.239 | G29: =G15*Hypothèses!$B$22 -> 36744.861 | H29: =H15*Hypothèses!$B$22 -> 43723.587 | I29: =I15*Hypothèses!$B$22 -> 51058.653 | J29: =J15*Hypothèses!$B$22 -> 58788.666 | ... AL29: =AL15*Hypothèses!$B$22 -> 394781.96
A30: Volume total qui passe par ScanLinkPay | B30: $ | C30: =C21+C22+C27+C29 -> 25368.24 | D30: =D21+D22+D27+D29 -> 37037.129 | E30: =E21+E22+E27+E29 -> 49249.726 | F30: =F21+F22+F27+F29 -> 62066.094 | G30: =G21+G22+G27+G29 -> 75550.353 | H30: =H21+H22+H27+H29 -> 91271.033 | I30: =I21+I22+I27+I29 -> 106421.47 | J30: =J21+J22+J27+J29 -> 122469.8 | ... AL30: =AL21+AL22+AL27+AL29 -> 889335
A32: Recettes (prix payés, TVA comprise si applicable)
A33: Commissions — paiements chez commerçants et entreprises | B33: $ | C33: =C21*Hypothèses!$B$16 -> 304.75 | D33: =D21*Hypothèses!$B$16 -> 441.4075 | E33: =E21*Hypothèses!$B$16 -> 585.62928 | F33: =F21*Hypothèses!$B$16 -> 738.12152 | G33: =G21*Hypothèses!$B$16 -> 899.64388 | H33: =H21*Hypothèses!$B$16 -> 1071.0139 | I33: =I21*Hypothèses!$B$16 -> 1253.1115 | J33: =J21*Hypothèses!$B$16 -> 1446.8844 | ... AL33: =AL21*Hypothèses!$B$16 -> 10872.479
A34: Commissions — commandes entre entreprises | B34: $ | C34: =C22*Hypothèses!$B$16 -> 16.956 | D34: =D22*Hypothèses!$B$16 -> 23.44572 | E34: =E22*Hypothèses!$B$16 -> 30.30062 | F34: =F22*Hypothèses!$B$16 -> 37.554536 | G34: =G22*Hypothèses!$B$16 -> 45.243868 | H34: =H22*Hypothèses!$B$16 -> 53.407798 | I34: =I22*Hypothèses!$B$16 -> 62.08851 | J34: =J22*Hypothèses!$B$16 -> 71.331435 | ... AL34: =AL22*Hypothèses!$B$16 -> 522.68065
A35: Commissions — applications partenaires (API) | B35: $ | C35: =C23*Hypothèses!$F$38+C24*Hypothèses!$F$39+C25*Hypothèses!$F$40+C26*Hypothèses!$F$41 -> 20 | D35: =D23*Hypothèses!$F$38+D24*Hypothèses!$F$39+D25*Hypothèses!$F$40+D26*Hypothèses!$F$41 -> 21.2 | E35: =E23*Hypothèses!$F$38+E24*Hypothèses!$F$39+E25*Hypothèses!$F$40+E26*Hypothèses!$F$41 -> 22.472 | F35: =F23*Hypothèses!$F$38+F24*Hypothèses!$F$39+F25*Hypothèses!$F$40+F26*Hypothèses!$F$41 -> 23.82032 | G35: =G23*Hypothèses!$F$38+G24*Hypothèses!$F$39+G25*Hypothèses!$F$40+G26*Hypothèses!$F$41 -> 25.249539 | H35: =H23*Hypothèses!$F$38+H24*Hypothèses!$F$39+H25*Hypothèses!$F$40+H26*Hypothèses!$F$41 -> 64.264512 | I35: =I23*Hypothèses!$F$38+I24*Hypothèses!$F$39+I25*Hypothèses!$F$40+I26*Hypothèses!$F$41 -> 68.870382 | J35: =J23*Hypothèses!$F$38+J24*Hypothèses!$F$39+J25*Hypothèses!$F$40+J26*Hypothèses!$F$41 -> 73.812605 | ... AL35: =AL23*Hypothèses!$F$38+AL24*Hypothèses!$F$39+AL25*Hypothèses!$F$40+AL26*Hypothèses!$F$41 -> 968.66662
A36: Frais de retrait | B36: $ | C36: =C28*Hypothèses!$B$19 -> 77.20944 | D36: =D28*Hypothèses!$B$19 -> 111.56477 | E36: =E28*Hypothèses!$B$19 -> 147.82317 | F36: =F28*Hypothèses!$B$19 -> 186.16225 | G36: =G28*Hypothèses!$B$19 -> 226.77306 | H36: =H28*Hypothèses!$B$19 -> 269.8612 | I36: =I28*Hypothèses!$B$19 -> 315.648 | J36: =J28*Hypothèses!$B$19 -> 364.3718 | ... AL36: =AL28*Hypothèses!$B$19 -> 2734.8382
A37: Frais de transfert | B37: $ | C37: =C29*Hypothèses!$B$21 -> 0 | D37: =D29*Hypothèses!$B$21 -> 0 | E37: =E29*Hypothèses!$B$21 -> 0 | F37: =F29*Hypothèses!$B$21 -> 0 | G37: =G29*Hypothèses!$B$21 -> 0 | H37: =H29*Hypothèses!$B$21 -> 0 | I37: =I29*Hypothèses!$B$21 -> 0 | J37: =J29*Hypothèses!$B$21 -> 0 | ... AL37: =AL29*Hypothèses!$B$21 -> 0
A38: Abonnements entreprises | B38: $ | C38: =C11*Hypothèses!$B$27 -> 70.65 | D38: =D11*Hypothèses!$B$27 -> 97.6905 | E38: =E11*Hypothèses!$B$27 -> 126.25258 | F38: =F11*Hypothèses!$B$27 -> 156.47723 | G38: =G11*Hypothèses!$B$27 -> 188.51612 | H38: =H11*Hypothèses!$B$27 -> 222.53249 | I38: =I11*Hypothèses!$B$27 -> 258.70212 | J38: =J11*Hypothèses!$B$27 -> 297.21431 | ... AL38: =AL11*Hypothèses!$B$27 -> 2177.836
A39: Abonnements Fournisseur | B39: $ | C39: =C17*Hypothèses!$B$29*((1-Hypothèses!$B$31)+Hypothèses!$B$31*(12-Hypothèses!$B$30)/12) -> 6.71175 | D39: =D17*Hypothèses!$B$29*((1-Hypothèses!$B$31)+Hypothèses!$B$31*(12-Hypothèses!$B$30)/12) -> 9.2805975 | E39: =E17*Hypothèses!$B$29*((1-Hypothèses!$B$31)+Hypothèses!$B$31*(12-Hypothèses!$B$30)/12) -> 11.993996 | F39: =F17*Hypothèses!$B$29*((1-Hypothèses!$B$31)+Hypothèses!$B$31*(12-Hypothèses!$B$30)/12) -> 14.865337 | G39: =G17*Hypothèses!$B$29*((1-Hypothèses!$B$31)+Hypothèses!$B$31*(12-Hypothèses!$B$30)/12) -> 17.909031 | H39: =H17*Hypothèses!$B$29*((1-Hypothèses!$B$31)+Hypothèses!$B$31*(12-Hypothèses!$B$30)/12) -> 21.140587 | I39: =I17*Hypothèses!$B$29*((1-Hypothèses!$B$31)+Hypothèses!$B$31*(12-Hypothèses!$B$30)/12) -> 24.576702 | J39: =J17*Hypothèses!$B$29*((1-Hypothèses!$B$31)+Hypothèses!$B$31*(12-Hypothèses!$B$30)/12) -> 28.23536 | ... AL39: =AL17*Hypothèses!$B$29*((1-Hypothèses!$B$31)+Hypothèses!$B$31*(12-Hypothèses!$B$30)/12) -> 206.89442
A40: Mes dépenses Pro | B40: $ | C40: =C15*Scénarios!$E$18*Hypothèses!$B$32/Hypothèses!$B$8 -> 13.684211 | D40: =D15*Scénarios!$E$18*Hypothèses!$B$32/Hypothèses!$B$8 -> 20.578947 | E40: =E15*Scénarios!$E$18*Hypothèses!$B$32/Hypothèses!$B$8 -> 27.735263 | F40: =F15*Scénarios!$E$18*Hypothèses!$B$32/Hypothèses!$B$8 -> 35.188584 | G40: =G15*Scénarios!$E$18*Hypothèses!$B$32/Hypothèses!$B$8 -> 42.976446 | H40: =H15*Scénarios!$E$18*Hypothèses!$B$32/Hypothèses!$B$8 -> 51.138698 | I40: =I15*Scénarios!$E$18*Hypothèses!$B$32/Hypothèses!$B$8 -> 59.717723 | J40: =J15*Scénarios!$E$18*Hypothèses!$B$32/Hypothèses!$B$8 -> 68.758674 | ... AL40: =AL15*Scénarios!$E$18*Hypothèses!$B$32/Hypothèses!$B$8 -> 461.73329
A41: Recettes encaissées | B41: $ | C41: =SUM(C33:C40) -> 509.9614 | D41: =SUM(D33:D40) -> 725.16804 | E41: =SUM(E33:E40) -> 952.20691 | F41: =SUM(F33:F40) -> 1192.1898 | G41: =SUM(G33:G40) -> 1446.3119 | H41: =SUM(H33:H40) -> 1753.3591 | I41: =SUM(I33:I40) -> 2042.7149 | J41: =SUM(J33:J40) -> 2350.6086 | ... AL41: =SUM(AL33:AL40) -> 17945.128
A42: TVA reversée à l’État | B42: $ | C42: =C41-C41/(1+Hypothèses!$B$10*Hypothèses!$B$11) -> 70.339504 | D42: =D41-D41/(1+Hypothèses!$B$10*Hypothèses!$B$11) -> 100.02318 | E42: =E41-E41/(1+Hypothèses!$B$10*Hypothèses!$B$11) -> 131.33888 | F42: =F41-F41/(1+Hypothèses!$B$10*Hypothèses!$B$11) -> 164.43997 | G42: =G41-G41/(1+Hypothèses!$B$10*Hypothèses!$B$11) -> 199.4913 | H42: =H41-H41/(1+Hypothèses!$B$10*Hypothèses!$B$11) -> 241.84264 | I42: =I41-I41/(1+Hypothèses!$B$10*Hypothèses!$B$11) -> 281.75378 | J42: =J41-J41/(1+Hypothèses!$B$10*Hypothèses!$B$11) -> 324.22188 | ... AL42: =AL41-AL41/(1+Hypothèses!$B$10*Hypothèses!$B$11) -> 2475.1901
A43: Chiffre d’affaires net (hors TVA) | B43: $ | C43: =C41-C42 -> 439.6219 | D43: =D41-D42 -> 625.14486 | E43: =E41-E42 -> 820.86803 | F43: =F41-F42 -> 1027.7498 | G43: =G41-G42 -> 1246.8206 | H43: =H41-H42 -> 1511.5165 | I43: =I41-I42 -> 1760.9611 | J43: =J41-J42 -> 2026.3867 | ... AL43: =AL41-AL42 -> 15469.938
A45: Coûts
...

Sheet Synthèse
A1: Synthèse sur 3 ans
A2: ="Scénario : "&Hypothèses!$B$7&" · montants en USD (CDF au taux de "&TEXT(Hypothèses!$B$8,"#,##0")&" pour 1 $)" -> Scénario : Réaliste · montants en USD (CDF au taux de 2,850 pour 1 $)
A4: Indicateur | B4: An 1 | C4: An 2 | D4: An 3 | E4: Total 3 ans | G4: Repères clés
A5: Utilisateurs en fin d’année | G5: Premier mois bénéficiaire | H5: =IF(MIN(Prévisions!$C$60:$AL$60)=999,"Pas en 3 ans","Mois "&MIN(Prévisions!$C$60:$AL$60)) -> Mois 16
A6: Entreprises actives | B6: =INDEX(Prévisions!$C$10:$AL$10,12) -> 53.223605 | C6: =INDEX(Prévisions!$C$10:$AL$10,24) -> 131.20803 | D6: =INDEX(Prévisions!$C$10:$AL$10,36) -> 241.98178 | E6: =D6 -> 241.98178 | G6: Investissement remboursé (trésorerie > 0) | H6: =IF(MIN(Prévisions!$C$61:$AL$61)=999,"Pas en 3 ans","Mois "&MIN(Prévisions!$C$61:$AL$61)) -> Mois 29
A7: Commerçants actifs | B7: =INDEX(Prévisions!$C$13:$AL$13,12) -> 172.7864 | C7: =INDEX(Prévisions!$C$13:$AL$13,24) -> 434.15064 | D7: =INDEX(Prévisions!$C$13:$AL$13,36) -> 804.37908 | E7: =D7 -> 804.37908 | G7: Besoin de trésorerie maximal | H7: =-MIN(0,MIN(Prévisions!$C$58:$AL$58)) -> 15455.281
A8: Clients actifs | B8: =INDEX(Prévisions!$C$15:$AL$15,12) -> 3150.8567 | C8: =INDEX(Prévisions!$C$15:$AL$15,24) -> 7418.2165 | D8: =INDEX(Prévisions!$C$15:$AL$15,36) -> 13159.399 | E8: =D8 -> 13159.399 | G8: Bénéfice net du mois 36 | H8: =INDEX(Prévisions!$C$57:$AL$57,36) -> 4153.0636
A9: Fournisseurs abonnés | B9: =INDEX(Prévisions!$C$17:$AL$17,12) -> 4.7901245 | C9: =INDEX(Prévisions!$C$17:$AL$17,24) -> 11.808722 | D9: =INDEX(Prévisions!$C$17:$AL$17,36) -> 21.77836 | E9: =D9 -> 21.77836 | G9: Trésorerie cumulée à 3 ans | H9: =INDEX(Prévisions!$C$58:$AL$58,36) -> 23796.923
G10: Part des abonnements dans le CA (an 3) | H10: =IF(D24=0,0,(D21+D22+D23)/(1+Hypothèses!$B$10*Hypothèses!$B$11)/D24) -> 0.16000933
A11: Volumes | G11: Part de l’API partenaires dans le CA (an 3) | H11: =IF(D24=0,0,D18/(1+Hypothèses!$B$10*Hypothèses!$B$11)/D24) -> 0.048203464
A12: Volume total qui passe par ScanLinkPay | B12: =SUMIF(Prévisions!$C$5:$AL$5,1,Prévisions!$C$30:$AL$30) -> 1242362.7 | C12: =SUMIF(Prévisions!$C$5:$AL$5,2,Prévisions!$C$30:$AL$30) -> 4167499.2 | D12: =SUMIF(Prévisions!$C$5:$AL$5,3,Prévisions!$C$30:$AL$30) -> 8286111.9 | E12: =SUM(B12:D12) -> 13695974
A13: dont paiements via l’API des applications partenaires | B13: =SUMIF(Prévisions!$C$5:$AL$5,1,Prévisions!$C$27:$AL$27) -> 28380.158 | C13: =SUMIF(Prévisions!$C$5:$AL$5,2,Prévisions!$C$27:$AL$27) -> 124530.25 | D13: =SUMIF(Prévisions!$C$5:$AL$5,3,Prévisions!$C$27:$AL$27) -> 319956.52 | E13: =SUM(B13:D13) -> 472866.93
A15: Recettes par source (TVA comprise)
A16: Commissions — paiements commerçants / entreprises | B16: =SUMIF(Prévisions!$C$5:$AL$5,1,Prévisions!$C$33:$AL$33) -> 14736.769 | C16: =SUMIF(Prévisions!$C$5:$AL$5,2,Prévisions!$C$33:$AL$33) -> 50151.894 | D16: =SUMIF(Prévisions!$C$5:$AL$5,3,Prévisions!$C$33:$AL$33) -> 101095.39 | E16: =SUM(B16:D16) -> 165984.06
A17: Commissions — commandes entre entreprises | B17: =SUMIF(Prévisions!$C$5:$AL$5,1,Prévisions!$C$34:$AL$34) -> 731.12273 | C17: =SUMIF(Prévisions!$C$5:$AL$5,2,Prévisions!$C$34:$AL$34) -> 2423.7751 | D17: =SUMIF(Prévisions!$C$5:$AL$5,3,Prévisions!$C$34:$AL$34) -> 4864.0163 | E17: =SUM(B17:D17) -> 8018.9141
A18: Commissions — applications partenaires (API) | B18: =SUMIF(Prévisions!$C$5:$AL$5,1,Prévisions!$C$35:$AL$35) -> 709.50395 | C18: =SUMIF(Prévisions!$C$5:$AL$5,2,Prévisions!$C$35:$AL$35) -> 3113.2563 | D18: =SUMIF(Prévisions!$C$5:$AL$5,3,Prévisions!$C$35:$AL$35) -> 7998.9131 | E18: =SUM(B18:D18) -> 11821.673
A19: Frais de retrait | B19: =SUMIF(Prévisions!$C$5:$AL$5,1,Prévisions!$C$36:$AL$36) -> 3712.294 | C19: =SUMIF(Prévisions!$C$5:$AL$5,2,Prévisions!$C$36:$AL$36) -> 12618.161 | D19: =SUMIF(Prévisions!$C$5:$AL$5,3,Prévisions!$C$36:$AL$36) -> 25430.258 | E19: =SUM(B19:D19) -> 41760.713
A20: Frais de transfert | B20: =SUMIF(Prévisions!$C$5:$AL$5,1,Prévisions!$C$37:$AL$37) -> 0 | C20: =SUMIF(Prévisions!$C$5:$AL$5,2,Prévisions!$C$37:$AL$37) -> 0 | D20: =SUMIF(Prévisions!$C$5:$AL$5,3,Prévisions!$C$37:$AL$37) -> 0 | E20: =SUM(B20:D20) -> 0
A21: Abonnements entreprises | B21: =SUMIF(Prévisions!$C$5:$AL$5,1,Prévisions!$C$38:$AL$38) -> 3046.3447 | C21: =SUMIF(Prévisions!$C$5:$AL$5,2,Prévisions!$C$38:$AL$38) -> 10099.063 | D21: =SUMIF(Prévisions!$C$5:$AL$5,3,Prévisions!$C$38:$AL$38) -> 20266.734 | E21: =SUM(B21:D21) -> 33412.142
A22: Abonnements Fournisseur | B22: =SUMIF(Prévisions!$C$5:$AL$5,1,Prévisions!$C$39:$AL$39) -> 289.40275 | C22: =SUMIF(Prévisions!$C$5:$AL$5,2,Prévisions!$C$39:$AL$39) -> 959.41098 | D22: =SUMIF(Prévisions!$C$5:$AL$5,3,Prévisions!$C$39:$AL$39) -> 1925.3398 | E22: =SUM(B22:D22) -> 3174.1535
A23: Mes dépenses Pro | B23: =SUMIF(Prévisions!$C$5:$AL$5,1,Prévisions!$C$40:$AL$40) -> 696.21856 | C23: =SUMIF(Prévisions!$C$5:$AL$5,2,Prévisions!$C$40:$AL$40) -> 2268.9383 | D23: =SUMIF(Prévisions!$C$5:$AL$5,3,Prévisions!$C$40:$AL$40) -> 4359.9754 | E23: =SUM(B23:D23) -> 7325.1322
A24: Chiffre d’affaires net (hors TVA) | B24: =SUMIF(Prévisions!$C$5:$AL$5,1,Prévisions!$C$43:$AL$43) -> 20622.117 | C24: =SUMIF(Prévisions!$C$5:$AL$5,2,Prévisions!$C$43:$AL$43) -> 70374.568 | D24: =SUMIF(Prévisions!$C$5:$AL$5,3,Prévisions!$C$43:$AL$43) -> 143052.27 | E24: =SUM(B24:D24) -> 234048.95
A26: Coûts et résultat
A27: FlexPaie — retraits | B27: =SUMIF(Prévisions!$C$5:$AL$5,1,Prévisions!$C$46:$AL$46) -> 7424.5879 | C27: =SUMIF(Prévisions!$C$5:$AL$5,2,Prévisions!$C$46:$AL$46) -> 25236.321 | D27: =SUMIF(Prévisions!$C$5:$AL$5,3,Prévisions!$C$46:$AL$46) -> 50860.516 | E27: =SUM(B27:D27) -> 83521.425
A28: Acquisition | B28: =SUMIF(Prévisions!$C$5:$AL$5,1,Prévisions!$C$50:$AL$50) -> 2561.9121 | C28: =SUMIF(Prévisions!$C$5:$AL$5,2,Prévisions!$C$50:$AL$50) -> 4918.8795 | D28: =SUMIF(Prévisions!$C$5:$AL$5,3,Prévisions!$C$50:$AL$50) -> 7875.2845 | E28: =SUM(B28:D28) -> 15356.076
A29: Coûts fixes | B29: =SUMIF(Prévisions!$C$5:$AL$5,1,Prévisions!$C$51:$AL$51) -> 23724 | C29: =SUMIF(Prévisions!$C$5:$AL$5,2,Prévisions!$C$51:$AL$51) -> 29655 | D29: =SUMIF(Prévisions!$C$5:$AL$5,3,Prévisions!$C$51:$AL$51) -> 37068.75 | E29: =SUM(B29:D29) -> 90447.75
A30: Total des coûts | B30: =SUMIF(Prévisions!$C$5:$AL$5,1,Prévisions!$C$52:$AL$52) -> 34159.263 | C30: =SUMIF(Prévisions!$C$5:$AL$5,2,Prévisions!$C$52:$AL$52) -> 60786.607 | D30: =SUMIF(Prévisions!$C$5:$AL$5,3,Prévisions!$C$52:$AL$52) -> 97458.783 | E30: =SUM(B30:D30) -> 192404.65
A31: Résultat avant impôt | B31: =SUMIF(Prévisions!$C$5:$AL$5,1,Prévisions!$C$55:$AL$55) -> -13537.147 | C31: =SUMIF(Prévisions!$C$5:$AL$5,2,Prévisions!$C$55:$AL$55) -> 9587.9602 | D31: =SUMIF(Prévisions!$C$5:$AL$5,3,Prévisions!$C$55:$AL$55) -> 45593.483 | E31: =SUM(B31:D31) -> 41644.297
A32: Bénéfice net | B32: =SUMIF(Prévisions!$C$5:$AL$5,1,Prévisions!$C$57:$AL$57) -> -13537.147 | C32: =SUMIF(Prévisions!$C$5:$AL$5,2,Prévisions!$C$57:$AL$57) -> 6443.6317 | D32: =SUMIF(Prévisions!$C$5:$AL$5,3,Prévisions!$C$57:$AL$57) -> 31915.438 | E32: =SUM(B32:D32) -> 24821.923
A33: Marge nette | B33: =IF(B24=0,0,B32/B24) -> -0.65643828 | C33: =IF(C24=0,0,C32/C24) -> 0.091561937 | D33: =IF(D24=0,0,D32/D24) -> 0.22310334 | E33: =IF(E24=0,0,E32/E24) -> 0.10605441

Sheet Prix
A1: Fixer les prix des abonnements
A2: Combien rapporte chaque prix, selon le nombre d’abonnés. Valeurs hors TVA (si TVA activée).
A4: Diviseur TVA | B4: =1+Hypothèses!$B$10*Hypothèses!$B$11 -> 1.16
A6: A. Abonnement entreprise — recettes de l’an 1 selon le prix et la part qui paie
A7: Mois-entreprises actifs sur l’an 1 (scénario) | B7: =SUMIF(Prévisions!$C$5:$AL$5,1,Prévisions!$C$10:$AL$10) -> 338.48275
A8: Prix / mois ($) ↓ Part qui paie → | B8: 0.4 | C8: 0.5 | D8: 0.6 | E8: 0.7 | F8: 0.8
A9: 5 | B9: =$A9*B$8*$B$7/Prix!$B$4 -> 583.59094 | C9: =$A9*C$8*$B$7/Prix!$B$4 -> 729.48868 | D9: =$A9*D$8*$B$7/Prix!$B$4 -> 875.38641 | E9: =$A9*E$8*$B$7/Prix!$B$4 -> 1021.2841 | F9: =$A9*F$8*$B$7/Prix!$B$4 -> 1167.1819
A10: 10 | B10: =$A10*B$8*$B$7/Prix!$B$4 -> 1167.1819 | C10: =$A10*C$8*$B$7/Prix!$B$4 -> 1458.9774 | D10: =$A10*D$8*$B$7/Prix!$B$4 -> 1750.7728 | E10: =$A10*E$8*$B$7/Prix!$B$4 -> 2042.5683 | F10: =$A10*F$8*$B$7/Prix!$B$4 -> 2334.3638
A11: 15 | B11: =$A11*B$8*$B$7/Prix!$B$4 -> 1750.7728 | C11: =$A11*C$8*$B$7/Prix!$B$4 -> 2188.466 | D11: =$A11*D$8*$B$7/Prix!$B$4 -> 2626.1592 | E11: =$A11*E$8*$B$7/Prix!$B$4 -> 3063.8524 | F11: =$A11*F$8*$B$7/Prix!$B$4 -> 3501.5457
A12: 20 | B12: =$A12*B$8*$B$7/Prix!$B$4 -> 2334.3638 | C12: =$A12*C$8*$B$7/Prix!$B$4 -> 2917.9547 | D12: =$A12*D$8*$B$7/Prix!$B$4 -> 3501.5457 | E12: =$A12*E$8*$B$7/Prix!$B$4 -> 4085.1366 | F12: =$A12*F$8*$B$7/Prix!$B$4 -> 4668.7275
A13: 25 | B13: =$A13*B$8*$B$7/Prix!$B$4 -> 2917.9547 | C13: =$A13*C$8*$B$7/Prix!$B$4 -> 3647.4434 | D13: =$A13*D$8*$B$7/Prix!$B$4 -> 4376.9321 | E13: =$A13*E$8*$B$7/Prix!$B$4 -> 5106.4207 | F13: =$A13*F$8*$B$7/Prix!$B$4 -> 5835.9094
A14: 30 | B14: =$A14*B$8*$B$7/Prix!$B$4 -> 3501.5457 | C14: =$A14*C$8*$B$7/Prix!$B$4 -> 4376.9321 | D14: =$A14*D$8*$B$7/Prix!$B$4 -> 5252.3185 | E14: =$A14*E$8*$B$7/Prix!$B$4 -> 6127.7049 | F14: =$A14*F$8*$B$7/Prix!$B$4 -> 7003.0913
A15: Ligne surlignée = votre prix actuel. Plus le prix est haut, plus il faut de valeur visible (caisse, stock, rapports, fournisseurs) pour garder la même part qui paie.
A17: B. Abonnement Fournisseur — recettes par mois selon le prix et le nombre de fournisseurs abonnés
A18: Facteur annuel (part à l’année × mois offerts) | B18: =(1-Hypothèses!$B$31)+Hypothèses!$B$31*(12-Hypothèses!$B$30)/12 -> 0.95
A19: Prix / mois ($) ↓ Fournisseurs abonnés → | B19: 10 | C19: 25 | D19: 50 | E19: 100 | F19: 200 | G19: 500
A20: 5 | B20: =$A20*B$19*$B$18/Prix!$B$4 -> 40.948276 | C20: =$A20*C$19*$B$18/Prix!$B$4 -> 102.37069 | D20: =$A20*D$19*$B$18/Prix!$B$4 -> 204.74138 | E20: =$A20*E$19*$B$18/Prix!$B$4 -> 409.48276 | F20: =$A20*F$19*$B$18/Prix!$B$4 -> 818.96552 | G20: =$A20*G$19*$B$18/Prix!$B$4 -> 2047.4138
A21: 8 | B21: =$A21*B$19*$B$18/Prix!$B$4 -> 65.517241 | C21: =$A21*C$19*$B$18/Prix!$B$4 -> 163.7931 | D21: =$A21*D$19*$B$18/Prix!$B$4 -> 327.58621 | E21: =$A21*E$19*$B$18/Prix!$B$4 -> 655.17241 | F21: =$A21*F$19*$B$18/Prix!$B$4 -> 1310.3448 | G21: =$A21*G$19*$B$18/Prix!$B$4 -> 3275.8621
A22: 10 | B22: =$A22*B$19*$B$18/Prix!$B$4 -> 81.896552 | C22: =$A22*C$19*$B$18/Prix!$B$4 -> 204.74138 | D22: =$A22*D$19*$B$18/Prix!$B$4 -> 409.48276 | E22: =$A22*E$19*$B$18/Prix!$B$4 -> 818.96552 | F22: =$A22*F$19*$B$18/Prix!$B$4 -> 1637.931 | G22: =$A22*G$19*$B$18/Prix!$B$4 -> 4094.8276
A23: 15 | B23: =$A23*B$19*$B$18/Prix!$B$4 -> 122.84483 | C23: =$A23*C$19*$B$18/Prix!$B$4 -> 307.11207 | D23: =$A23*D$19*$B$18/Prix!$B$4 -> 614.22414 | E23: =$A23*E$19*$B$18/Prix!$B$4 -> 1228.4483 | F23: =$A23*F$19*$B$18/Prix!$B$4 -> 2456.8966 | G23: =$A23*G$19*$B$18/Prix!$B$4 -> 6142.2414
A24: 20 | B24: =$A24*B$19*$B$18/Prix!$B$4 -> 163.7931 | C24: =$A24*C$19*$B$18/Prix!$B$4 -> 409.48276 | D24: =$A24*D$19*$B$18/Prix!$B$4 -> 818.96552 | E24: =$A24*E$19*$B$18/Prix!$B$4 -> 1637.931 | F24: =$A24*F$19*$B$18/Prix!$B$4 -> 3275.8621 | G24: =$A24*G$19*$B$18/Prix!$B$4 -> 8189.6552
A25: 25 | B25: =$A25*B$19*$B$18/Prix!$B$4 -> 204.74138 | C25: =$A25*C$19*$B$18/Prix!$B$4 -> 511.85345 | D25: =$A25*D$19*$B$18/Prix!$B$4 -> 1023.7069 | E25: =$A25*E$19*$B$18/Prix!$B$4 -> 2047.4138 | F25: =$A25*F$19*$B$18/Prix!$B$4 -> 4094.8276 | G25: =$A25*G$19*$B$18/Prix!$B$4 -> 10237.069
A27: C. Formule annuelle Fournisseur — ce que coûte l’année selon les mois offerts
A28: Mois offerts | B28: Prix de l’année ($) | C28: Réduction | D28: Équivalent par mois ($)
A29: 0 | B29: =Hypothèses!$B$29*(12-A29) -> 120 | C29: =A29/12 -> 0 | D29: =B29/12 -> 10
A30: 1 | B30: =Hypothèses!$B$29*(12-A30) -> 110 | C30: =A30/12 -> 0.083333333 | D30: =B30/12 -> 9.1666667
A31: 2 | B31: =Hypothèses!$B$29*(12-A31) -> 100 | C31: =A31/12 -> 0.16666667 | D31: =B31/12 -> 8.3333333
A32: 3 | B32: =Hypothèses!$B$29*(12-A32) -> 90 | C32: =A32/12 -> 0.25 | D32: =B32/12 -> 7.5
A33: 4 | B33: =Hypothèses!$B$29*(12-A33) -> 80 | C33: =A33/12 -> 0.33333333 | D33: =B33/12 -> 6.6666667
A35: D. Ce que rapporte un utilisateur par mois (hors TVA, scénario actif)
A36: Type d’utilisateur | B36: Recette / mois ($) | C36: Coût direct / mois ($) | D36: Contribution ($) | E36: Commentaire
A37: Commerçant | B37: =Scénarios!$E$16*(Hypothèses!$B$16+Hypothèses!$B$18*Hypothèses!$B$19)/Prix!$B$4 -> 8.0172414 | C37: =Scénarios!$E$16*(Hypothèses!$B$18*Hypothèses!$B$20+Hypothèses!$B$17) -> 3.6 | D37: =B37-C37 -> 4.4172414 | E37: Commission + frais de retrait − coût FlexPaie.
A38: Entreprise (abonnée) | B38: =(Scénarios!$E$17*(Hypothèses!$B$16+Hypothèses!$B$18*Hypothèses!$B$19)+Hypothèses!$B$27)/Prix!$B$4 -> 34.310345 | C38: =Scénarios!$E$17*(Hypothèses!$B$18*Hypothèses!$B$20+Hypothèses!$B$17) -> 9.6 | D38: =B38-C38 -> 24.710345 | E38: Avec l’abonnement.
A39: Fournisseur (abonné) | B39: =(Hypothèses!$B$29*$B$18+Scénarios!$E$21*Scénarios!$E$22*Scénarios!$E$23*(Hypothèses!$B$16+Hypothèses!$B$18*Hypothèses!$B$19))/Prix!$B$4 -> 33.844828 | C39: =Scénarios!$E$21*Scénarios!$E$22*Scénarios!$E$23*(Hypothèses!$B$18*Hypothèses!$B$20+Hypothèses!$B$17) -> 11.52 | D39: =B39-C39 -> 22.324828 | E39: Abonnement + commissions sur ses ventes payées par ScanLinkPay.
A40: Client (avec Pro) | B40: =(Hypothèses!$B$32/Hypothèses!$B$8+Hypothèses!$B$22*Hypothèses!$B$21)/Prix!$B$4 -> 1.5124017 | C40: =0 -> 0 | D40: =B40-C40 -> 1.5124017 | E40: Le client paie peu : il fait vivre les commerçants.

Sheet Rentabilité
A1: Seuil de rentabilité et objectif
A2: Combien de transactions, de commerçants ou d’abonnés faut-il pour couvrir les coûts et atteindre l’objectif ?
A4: A. Ce que rapporte 1 $ de paiement (hors TVA)
A5: Commission par $ payé | B5: =Hypothèses!$B$16/Prix!$B$4 -> 0.021551724
A6: Frais de retrait par $ payé (part retirée × frais) | B6: =Hypothèses!$B$18*Hypothèses!$B$19/Prix!$B$4 -> 0.0051724138
A7: Coût FlexPaie par $ payé (retraits + encaissements) | B7: =Hypothèses!$B$18*Hypothèses!$B$20+Hypothèses!$B$17 -> 0.012
A8: Contribution nette par $ payé | B8: =B5+B6-B7 -> 0.014724138
A9: Contribution par transaction moyenne | B9: =B8*Hypothèses!$B$23 -> 0.29448276
A11: B. Couvrir les coûts fixes (an 1)
A12: Coûts fixes mensuels (an 1) | B12: =Hypothèses!$B$55 -> 1977
A13: Abonnements entreprises et Fournisseur (moyenne mensuelle an 1, hors TVA) | B13: =(SUMIF(Prévisions!$C$5:$AL$5,1,Prévisions!$C$38:$AL$38)+SUMIF(Prévisions!$C$5:$AL$5,1,Prévisions!$C$39:$AL$39)+SUMIF(Prévisions!$C$5:$AL$5,1,Prévisions!$C$40:$AL$40))/12/Prix!$B$4 -> 289.65273
A14: Reste à couvrir par les paiements | B14: =MAX(0,B12-B13) -> 1687.3473
A15: Volume de paiements nécessaire par mois | B15: =IF(B8<=0,"Impossible : la contribution par $ est négative",B14/B8) -> 114597.36
A16: Soit, en transactions par mois | B16: =IF(ISNUMBER(B15),B15/Hypothèses!$B$23,"-") -> 5729.8678
A17: Soit, en commerçants actifs | B17: =IF(ISNUMBER(B15),B15/Scénarios!$E$16,"-") -> 381.99118
A18: Ou, en entreprises abonnées seules (abonnement + paiements) | B18: =IF(Prix!$D$38<=0,"-",B12/Prix!$D$38) -> 80.006977
A20: ="C. Objectif : bénéfice net de "&TEXT(Hypothèses!$B$77,"#,##0")&" £ par mois" -> C. Objectif : bénéfice net de 1,000 £ par mois
A21: Objectif en $ (net d’impôt) | B21: =Hypothèses!$B$77*Hypothèses!$B$9 -> 1270
A22: Résultat avant impôt nécessaire | B22: =B21/(1-Hypothèses!$B$12) -> 1814.2857
A23: Volume de paiements nécessaire par mois | B23: =IF(B8<=0,"Impossible",(B22+B14)/B8) -> 237815.82
A24: Soit, en transactions par mois | B24: =IF(ISNUMBER(B23),B23/Hypothèses!$B$23,"-") -> 11890.791
A25: Soit, en transactions par jour | B25: =IF(ISNUMBER(B24),B24/30,"-") -> 396.35971
A26: Soit, en commerçants actifs | B26: =IF(ISNUMBER(B23),B23/Scénarios!$E$16,"-") -> 792.71941
A27: Mois où le modèle atteint l’objectif (scénario actif) | B27: =IF(MIN(Prévisions!$C$62:$AL$62)=999,"Pas en 3 ans","Mois "&MIN(Prévisions!$C$62:$AL$62)) -> Mois 23
A29: D. Applications partenaires (API) — combien rapporte chaque application
A30: Transactions par application et par mois | B30: 500 | D30: Exemple HotelSaver : un hôtel paie son abonnement et ses clients leurs acomptes par l’API ScanLinkPay ; chaque paiement rapporte la commission.
A31: Montant moyen par transaction ($) | B31: 20
A32: Commission | B32: =Hypothèses!$B$16 -> 0.025
A33: Recette par application et par mois (hors TVA) | B33: =B30*B31*B32/Prix!$B$4 -> 215.51724
A35: Nombre d’applications | B35: Recette / mois ($) | C35: Recette / an ($) | D35: Part des coûts fixes couverte
A36: 1 | B36: =A36*$B$33 -> 215.51724 | C36: =B36*12 -> 2586.2069 | D36: =IF($B$12=0,0,B36/$B$12) -> 0.10901226
A37: 2 | B37: =A37*$B$33 -> 431.03448 | C37: =B37*12 -> 5172.4138 | D37: =IF($B$12=0,0,B37/$B$12) -> 0.21802452
A38: 4 | B38: =A38*$B$33 -> 862.06897 | C38: =B38*12 -> 10344.828 | D38: =IF($B$12=0,0,B38/$B$12) -> 0.43604905
A39: 6 | B39: =A39*$B$33 -> 1293.1034 | C39: =B39*12 -> 15517.241 | D39: =IF($B$12=0,0,B39/$B$12) -> 0.65407357
A40: 8 | B40: =A40*$B$33 -> 1724.1379 | C40: =B40*12 -> 20689.655 | D40: =IF($B$12=0,0,B40/$B$12) -> 0.87209809
A41: 10 | B41: =A41*$B$33 -> 2155.1724 | C41: =B41*12 -> 25862.069 | D41: =IF($B$12=0,0,B41/$B$12) -> 1.0901226
A43: Transactions nécessaires par application pour couvrir seule les coûts fixes | B43: =IF(B31*B32=0,"-",B12*Prix!$B$4/(B31*B32)) -> 4586.64

Sheet Retraits
A1: Frais de retrait : gain ou perte ?
A2: Le retrait vers Mobile Money coûte ~2 % chez FlexPaie. Nos frais doivent couvrir ce coût, plus la TVA.
A4: Volume retiré par mois (moyenne an 1, scénario) | B4: =SUMIF(Prévisions!$C$5:$AL$5,1,Prévisions!$C$28:$AL$28)/12 -> 30935.783
A5: Coût FlexPaie par retrait | B5: =Hypothèses!$B$20 -> 0.02
A6: Frais actuels (application) | B6: =Hypothèses!$B$19 -> 0.01
A8: Frais de retrait | B8: Recette hors TVA / 100 $ | C8: Coût / 100 $ | D8: Gain / 100 $ | E8: Gain par mois ($) | F8: Verdict
A9: 0.01 | B9: =100*A9/Prix!$B$4 -> 0.86206897 | C9: =100*$B$5 -> 2 | D9: =B9-C9 -> -1.137931 | E9: =$B$4/100*D9 -> -352.02787 | F9: =IF(D9<0,"Perte",IF(D9<0.3,"Juste","Rentable")) -> Perte
A10: 0.015 | B10: =100*A10/Prix!$B$4 -> 1.2931034 | C10: =100*$B$5 -> 2 | D10: =B10-C10 -> -0.70689655 | E10: =$B$4/100*D10 -> -218.68398 | F10: =IF(D10<0,"Perte",IF(D10<0.3,"Juste","Rentable")) -> Perte
A11: 0.02 | B11: =100*A11/Prix!$B$4 -> 1.7241379 | C11: =100*$B$5 -> 2 | D11: =B11-C11 -> -0.27586207 | E11: =$B$4/100*D11 -> -85.340091 | F11: =IF(D11<0,"Perte",IF(D11<0.3,"Juste","Rentable")) -> Perte
A12: 0.025 | B12: =100*A12/Prix!$B$4 -> 2.1551724 | C12: =100*$B$5 -> 2 | D12: =B12-C12 -> 0.15517241 | E12: =$B$4/100*D12 -> 48.003801 | F12: =IF(D12<0,"Perte",IF(D12<0.3,"Juste","Rentable")) -> Juste
A13: 0.03 | B13: =100*A13/Prix!$B$4 -> 2.5862069 | C13: =100*$B$5 -> 2 | D13: =B13-C13 -> 0.5862069 | E13: =$B$4/100*D13 -> 181.34769 | F13: =IF(D13<0,"Perte",IF(D13<0.3,"Juste","Rentable")) -> Rentable
A14: 0.035 | B14: =100*A14/Prix!$B$4 -> 3.0172414 | C14: =100*$B$5 -> 2 | D14: =B14-C14 -> 1.0172414 | E14: =$B$4/100*D14 -> 314.69159 | F14: =IF(D14<0,"Perte",IF(D14<0.3,"Juste","Rentable")) -> Rentable
A15: 0.04 | B15: =100*A15/Prix!$B$4 -> 3.4482759 | C15: =100*$B$5 -> 2 | D15: =B15-C15 -> 1.4482759 | E15: =$B$4/100*D15 -> 448.03548 | F15: =IF(D15<0,"Perte",IF(D15<0.3,"Juste","Rentable")) -> Rentable
A17: Recommandation : des frais de retrait d’au moins 2,5 % à 3 % (super admin → Frais et limites). La ligne surlignée = les frais actuels.

Sheet Sensibilité
A1: Sensibilité : commission et volume
A2: Résultat avant impôt du mois 12 si l’on change la commission et le volume des paiements (le reste ne bouge pas).
A4: Résultat avant impôt du mois 12 (scénario) | B4: =INDEX(Prévisions!$C$55:$AL$55,12) -> -228.25527
A5: Volume soumis à commission au mois 12 | B5: =INDEX(Prévisions!$C$21:$AL$21,12)+INDEX(Prévisions!$C$22:$AL$22,12)+INDEX(Prévisions!$C$27:$AL$27,12) -> 104412.27
A6: Commission actuelle | B6: =Hypothèses!$B$16 -> 0.025
A7: Marge retraits par $ payé (hors TVA) | B7: =Hypothèses!$B$18*(Hypothèses!$B$19/Prix!$B$4-Hypothèses!$B$20) -> -0.0068275862
A9: Commission ↓ Volume → | B9: 0.5 | C9: 0.75 | D9: 1 | E9: 1.5 | F9: 2 | G9: 3
A10: 0.01 | B10: =$B$4-$B$5*($B$6/Prix!$B$4+$B$7)+$B$5*B$9*($A10/Prix!$B$4+$B$7) -> -1672.025 | C10: =$B$4-$B$5*($B$6/Prix!$B$4+$B$7)+$B$5*C$9*($A10/Prix!$B$4+$B$7) -> -1625.2195 | D10: =$B$4-$B$5*($B$6/Prix!$B$4+$B$7)+$B$5*D$9*($A10/Prix!$B$4+$B$7) -> -1578.414 | E10: =$B$4-$B$5*($B$6/Prix!$B$4+$B$7)+$B$5*E$9*($A10/Prix!$B$4+$B$7) -> -1484.803 | F10: =$B$4-$B$5*($B$6/Prix!$B$4+$B$7)+$B$5*F$9*($A10/Prix!$B$4+$B$7) -> -1391.192 | G10: =$B$4-$B$5*($B$6/Prix!$B$4+$B$7)+$B$5*G$9*($A10/Prix!$B$4+$B$7) -> -1203.97
A11: 0.015 | B11: =$B$4-$B$5*($B$6/Prix!$B$4+$B$7)+$B$5*B$9*($A11/Prix!$B$4+$B$7) -> -1446.9985 | C11: =$B$4-$B$5*($B$6/Prix!$B$4+$B$7)+$B$5*C$9*($A11/Prix!$B$4+$B$7) -> -1287.6798 | D11: =$B$4-$B$5*($B$6/Prix!$B$4+$B$7)+$B$5*D$9*($A11/Prix!$B$4+$B$7) -> -1128.3611 | E11: =$B$4-$B$5*($B$6/Prix!$B$4+$B$7)+$B$5*E$9*($A11/Prix!$B$4+$B$7) -> -809.72363 | F11: =$B$4-$B$5*($B$6/Prix!$B$4+$B$7)+$B$5*F$9*($A11/Prix!$B$4+$B$7) -> -491.08617 | G11: =$B$4-$B$5*($B$6/Prix!$B$4+$B$7)+$B$5*G$9*($A11/Prix!$B$4+$B$7) -> 146.18875
A12: 0.02 | B12: =$B$4-$B$5*($B$6/Prix!$B$4+$B$7)+$B$5*B$9*($A12/Prix!$B$4+$B$7) -> -1221.9721 | C12: =$B$4-$B$5*($B$6/Prix!$B$4+$B$7)+$B$5*C$9*($A12/Prix!$B$4+$B$7) -> -950.14013 | D12: =$B$4-$B$5*($B$6/Prix!$B$4+$B$7)+$B$5*D$9*($A12/Prix!$B$4+$B$7) -> -678.30818 | E12: =$B$4-$B$5*($B$6/Prix!$B$4+$B$7)+$B$5*E$9*($A12/Prix!$B$4+$B$7) -> -134.64427 | F12: =$B$4-$B$5*($B$6/Prix!$B$4+$B$7)+$B$5*F$9*($A12/Prix!$B$4+$B$7) -> 409.01964 | G12: =$B$4-$B$5*($B$6/Prix!$B$4+$B$7)+$B$5*G$9*($A12/Prix!$B$4+$B$7) -> 1496.3475
A13: 0.025 | B13: =$B$4-$B$5*($B$6/Prix!$B$4+$B$7)+$B$5*B$9*($A13/Prix!$B$4+$B$7) -> -996.94564 | C13: =$B$4-$B$5*($B$6/Prix!$B$4+$B$7)+$B$5*C$9*($A13/Prix!$B$4+$B$7) -> -612.60045 | D13: =$B$4-$B$5*($B$6/Prix!$B$4+$B$7)+$B$5*D$9*($A13/Prix!$B$4+$B$7) -> -228.25527 | E13: =$B$4-$B$5*($B$6/Prix!$B$4+$B$7)+$B$5*E$9*($A13/Prix!$B$4+$B$7) -> 540.43509 | F13: =$B$4-$B$5*($B$6/Prix!$B$4+$B$7)+$B$5*F$9*($A13/Prix!$B$4+$B$7) -> 1309.1255 | G13: =$B$4-$B$5*($B$6/Prix!$B$4+$B$7)+$B$5*G$9*($A13/Prix!$B$4+$B$7) -> 2846.5062
A14: 0.03 | B14: =$B$4-$B$5*($B$6/Prix!$B$4+$B$7)+$B$5*B$9*($A14/Prix!$B$4+$B$7) -> -771.91918 | C14: =$B$4-$B$5*($B$6/Prix!$B$4+$B$7)+$B$5*C$9*($A14/Prix!$B$4+$B$7) -> -275.06077 | D14: =$B$4-$B$5*($B$6/Prix!$B$4+$B$7)+$B$5*D$9*($A14/Prix!$B$4+$B$7) -> 221.79764 | E14: =$B$4-$B$5*($B$6/Prix!$B$4+$B$7)+$B$5*E$9*($A14/Prix!$B$4+$B$7) -> 1215.5145 | F14: =$B$4-$B$5*($B$6/Prix!$B$4+$B$7)+$B$5*F$9*($A14/Prix!$B$4+$B$7) -> 2209.2313 | G14: =$B$4-$B$5*($B$6/Prix!$B$4+$B$7)+$B$5*G$9*($A14/Prix!$B$4+$B$7) -> 4196.6649
A15: 0.035 | B15: =$B$4-$B$5*($B$6/Prix!$B$4+$B$7)+$B$5*B$9*($A15/Prix!$B$4+$B$7) -> -546.89273 | C15: =$B$4-$B$5*($B$6/Prix!$B$4+$B$7)+$B$5*C$9*($A15/Prix!$B$4+$B$7) -> 62.478906 | D15: =$B$4-$B$5*($B$6/Prix!$B$4+$B$7)+$B$5*D$9*($A15/Prix!$B$4+$B$7) -> 671.85054 | E15: =$B$4-$B$5*($B$6/Prix!$B$4+$B$7)+$B$5*E$9*($A15/Prix!$B$4+$B$7) -> 1890.5938 | F15: =$B$4-$B$5*($B$6/Prix!$B$4+$B$7)+$B$5*F$9*($A15/Prix!$B$4+$B$7) -> 3109.3371 | G15: =$B$4-$B$5*($B$6/Prix!$B$4+$B$7)+$B$5*G$9*($A15/Prix!$B$4+$B$7) -> 5546.8236
A17: Lecture : en rouge, le mois 12 est en perte. « 1x » = le volume prévu ; « 2x » = deux fois plus de paiements.
